<?xml version="1.0"?>
<robot name="robot">

	<material name="red">
		<color rgba="0.8 0 0 1"/>
	</material>

	<material name="blue">
		<color rgba="0 0 0.8 1"/>
	</material>
	
	<material name="white">
		<color rgba="1 1 1 1"/>
	</material>

	<material name="black">
		<color rgba="0 0 0 1"/>
	</material>


	<link name="base_link">
		<visual>
			<geometry>
				<cylinder radius="0.7" length="0.02"/>
			</geometry>
			<material name="black"/>
			<origin rpy="0 0 0" xyz="0 0 0"/>
		</visual>
	</link>


	<link name="base_black">
		<visual>
			<geometry>
				<cylinder radius="0.6" length="0.31"/>
			</geometry>
			<material name="black"/>
			<origin rpy="0 0 0" xyz="0 0 0"/>
		</visual>
	</link>

	<joint name="base_link_black" type="fixed">
		<parent link="base_link"/>
		<child link="base_black"/>
		<origin rpy="0 0 0" xyz="0 0 0.17"/>
	</joint>

	<link name="base_box">
		<visual>
			<geometry>
				<box size="2.05 0.85 0.02"/>
			</geometry>
			<material name="black"/>
			<origin rpy="0 0 0" xyz="-0.325 0 0"/>
		</visual>
	</link>

	<joint name="base_link_box" type="fixed">
		<parent link="base_link"/>
		<child link="base_box"/>
		<origin rpy="0 0 0" xyz="-0.7 0 0"/>
	</joint>


	<link name="base_white">
		<visual>
			<geometry>
				<cylinder radius="0.6" length="0.08"/>
			</geometry>
			<material name="white"/>
		<origin rpy="0 0 0" xyz="0 0 -0.04"/>
		</visual>
	</link>


	<joint name="base_black_white" type="fixed">
		<parent link="base_black"/>
		<child link="base_white"/>
		<origin rpy="0 0 0" xyz="0 0 0.34"/>
	</joint>

	<link name="base_link_rot">
		<visual>
			<geometry>
				<cylinder radius="0.6" length="0.02"/>
			</geometry>
			<material name="black"/>
			<origin rpy="0 0 0" xyz="0 0 -0.01"/>
		</visual>
	</link>
		
	<joint name="joint0" type="revolute">
		<parent link="base_white"/>
		<child link="base_link_rot"/>
		<limit effort="1000.0" lower="-1.5707" upper="1.5707" velocity="0.5"/>
		<origin rpy="0 0 0" xyz="0 0 0.08"/>
		<axis xyz="0 0 1"/>
	</joint>

	

	<link name="link1">
		<visual>
			<geometry>
				<box size="0.58 0.46 0.25"/>
			</geometry>
			<origin rpy="0 0 0" xyz="0 0 0"/>
			<material name="red"/>
		</visual>
	</link>

	<joint name="base_link1" type="fixed">
		<parent link="base_link_rot"/>
		<child link="link1"/>
		<origin rpy="0 0 0" xyz="0.1 -0.03 0.125"/>
		<axis xyz="0 0 1"/>
	</joint>

	<link name="link1_rot1">
		<visual>
			<geometry>
				<cylinder radius="0.045" length="0.05"/>
			</geometry>
			<material name="white"/>
			<origin rpy="0 0 0" xyz="0 0 -0.025"/>
		</visual>
	</link>
		
	<joint name="joint1" type="revolute">
		<parent link="link1"/>
		<child link="link1_rot1"/>
		<limit effort="1000.0" lower="0" upper="3.1415" velocity="0.5"/>
		<origin rpy="1.5707 0 0" xyz="-0.1 0.23 0"/>
		<axis xyz="0 0 1"/>
	</joint>

	<link name="link1_rot2">
		<visual>
			<geometry>
				<cylinder radius="0.1" length="0.02"/>
			</geometry>
			<material name="white"/>
			<origin rpy="0 0 0" xyz="0 0 -0.01"/>
		</visual>
	</link>
		
	<joint name="link1_rot2_rot1" type="fixed">
		<parent link="link1_rot1"/>
		<child link="link1_rot2"/>
		<origin rpy="0 0 0" xyz="0 0 -0.05"/>
	</joint>

	<link name="link1_frame1">
		<visual>
			<geometry>
				<box size="0.65 0.25 0.02"/>
			</geometry>
			<material name="black"/>
			<origin rpy="0 0 0" xyz="-0.325 0 0"/>
		</visual>
	</link>

	<joint name="link1_rot2_frame1" type="fixed">
		<parent link="link1_rot2"/>
		<child link="link1_frame1"/>
		<origin rpy="0 0 0" xyz="0.52 0 -0.03"/>
	</joint>
	
	<link name="link1_frame2">
		<visual>
			<geometry>
				<box size="0.04 0.25 0.56"/>
			</geometry>
			<material name="black"/>
			<origin rpy="0 0 0" xyz="0 0 -0.28"/>
		</visual>
	</link>

	<joint name="link1_frame1_frame2" type="fixed">
		<parent link="link1_frame1"/>
		<child link="link1_frame2"/>
		<origin rpy="0 0 0" xyz="0 0 0.56"/>
	</joint>

	<link name="link1_frame3">
		<visual>
			<geometry>
				<box size="0.65 0.25 0.02"/>
			</geometry>
			<material name="black"/>
			<origin rpy="0 0 0" xyz="-0.325 0 0"/>
		</visual>
	</link>

	<joint name="link1_frame1_frame3" type="fixed">
		<parent link="link1_frame1"/>
		<child link="link1_frame3"/>
		<origin rpy="0 0 0" xyz="0.65 0 0"/>
	</joint>

	<link name="link1_frame4">
		<visual>
			<geometry>
				<box size="0.65 0.25 0.02"/>
			</geometry>
			<material name="black"/>
			<origin rpy="0 0 0" xyz="-0.325 0 0"/>
		</visual>
	</link>

	<joint name="link1_frame2_frame4" type="fixed">
		<parent link="link1_frame2"/>
		<child link="link1_frame4"/>
		<origin rpy="0 0 0" xyz="0 0 0"/>
	</joint>

	<link name="link1_frame5">
		<visual>
			<geometry>
				<box size="0.65 0.25 0.02"/>
			</geometry>
			<material name="black"/>
			<origin rpy="0 0 0" xyz="-0.325 0 0"/>
		</visual>
	</link>

	<joint name="link1_frame4_frame5" type="fixed">
		<parent link="link1_frame4"/>
		<child link="link1_frame5"/>
		<origin rpy="0 0 0" xyz="0.65 0 0"/>
	</joint>

	<link name="link2">
		<visual>
			<geometry>
				<box size="0.65 0.25 0.46"/>
			</geometry>	
			<material name="red"/>
			<origin rpy="0 0 0" xyz="-0.325 0 0"/>
		</visual>
	</link>

	<link name="link2_rot1">
		<visual>
			<geometry>
				<cylinder radius="0.045" length="0.05"/>
			</geometry>	
			<material name="white"/>
			<origin rpy="0 0 0" xyz="0 0 -0.025"/>
		</visual>
	</link>

	
	<link name="link2_rot2">
		<visual>
			<geometry>
				<cylinder radius="0.1" length="0.02"/>
			</geometry>	
			<material name="white"/>
			<origin rpy="0 0 0" xyz="0 0 -0.01"/>
		</visual>
	</link>


	<joint name="joint2" type="revolute">
		<parent link="link1_frame3"/>
		<child link="link2_rot1"/>
		<limit effort="1000.0" lower="-1.5707" upper="1.5707" velocity="0.5"/>
		<origin rpy="0 0 0" xyz="-0.12 0 0.08"/>
		<axis xyz="0 0 1"/>
	</joint>

	<joint name="link2_rot2_rot1" type="fixed">
		<parent link="link2_rot1"/>
		<child link="link2_rot2"/>
		<origin rpy="0 0 0" xyz="0 0 -0.05"/>
	</joint>

	<joint name="link2_rot1" type="fixed">
		<parent link="link2_rot2"/>
		<child link="link2"/>
		<origin rpy="0 0 0" xyz="0.27 0 0.28"/>
	</joint>

	<link name="link2_bar1">
		<visual>
			<geometry>
				<cylinder radius="0.1" length="0.03"/>
			</geometry>	
			<material name="white"/>
			<origin rpy="0 1.57 0" xyz="-0.015 0 0"/>
		</visual>
	</link>

	<!-- link2_bar1 will be a virtual revolute joint 
			 as well as link2_bar1_bar2 these should improve 
			the accurasy of kdl kinematic solver
	-->
	
	<joint name="link2_bar1" type="revolute">
		<parent link="link2"/>
		<child link="link2_bar1"/>
		<limit effort="1000.0" lower="-0.005" upper="0.005" velocity="0.5"/>
		<axis xyz="1 0 0"/>
		<origin rpy="0 0 0" xyz="0.03 0 0"/>
	</joint>

	<link name="link2_bar2">
		<visual>
			<geometry>
				<cylinder radius="0.05" length="0.5"/>
			</geometry>	
			<material name="white"/>
			<origin rpy="0 1.57 0" xyz="-0.25 0 0"/>
		</visual>
	</link>

	<joint name="link2_bar1_bar2" type="revolute">
		<parent link="link2_bar1"/>
		<child link="link2_bar2"/>
		<limit effort="1000.0" lower="-0.005" upper="0.005" velocity="0.5"/>
		<axis xyz="0 1 0"/>
		<origin rpy="0 0 0" xyz="0.5 0 0"/>
	</joint>

	<!-- !!!! END of virtual joints !!!!! -->
	
	<link name="link2_bar3">
		<visual>
			<geometry>
				<cylinder radius="0.1" length="0.03"/>
			</geometry>	
			<material name="white"/>
			<origin rpy="0 1.57 0" xyz="-0.015 0 0"/>
		</visual>
	</link>

	<joint name="link2_bar2_bar3" type="fixed">
		<parent link="link2_bar2"/>
		<child link="link2_bar3"/>
		<origin rpy="0 0 0" xyz="0.03 0 0"/>
	</joint>

	<link name="link3">
		<visual>
			<geometry>
				<box size="0.65 0.25 0.46"/>
			</geometry>	
			<material name="red"/>
			<origin rpy="0 0 0" xyz="0 0 0"/>
		</visual>
	</link>

	<joint name="link2_bar3_link3" type="fixed">
		<parent link="link2_bar3"/>
		<child link="link3"/>
		<origin rpy="0 0 0" xyz="0.325 0 0"/>
	</joint>

	<link name="link3_rot1">
		<visual>
			<geometry>
				<cylinder radius="0.045" length="0.05"/>
			</geometry>	
			<material name="white"/>
			<origin rpy="0 0 0" xyz="0 0 -0.025"/>
		</visual>
	</link>

	<joint name="joint3" type="revolute">
		<parent link="link3"/>
		<child link="link3_rot1"/>
		<limit effort="1000.0" lower="-1.5707" upper="1.5707" velocity="0.5"/>
		<origin rpy="0 0 0" xyz="0.155 0 -0.23"/>
		<axis xyz="0 0 1"/>
	</joint>
	
	<link name="link3_rot2">
		<visual>
			<geometry>
				<cylinder radius="0.1" length="0.02"/>
			</geometry>	
			<material name="white"/>
			<origin rpy="0 0 0" xyz="0 0 -0.01"/>
		</visual>
	</link>

	<joint name="link3_rot2_rot1" type="fixed">
		<parent link="link3_rot1"/>
		<child link="link3_rot2"/>
		<origin rpy="0 0 0" xyz="0 0 -0.05"/>
	</joint>

	<link name="link3_frame1">
		<visual>
			<geometry>
				<box size="0.65 0.25 0.02"/>
			</geometry>
			<material name="black"/>
			<origin rpy="0 0 0" xyz="-0.325 0 0"/>
		</visual>
	</link>

	<joint name="link3_rot2_frame1" type="fixed">
		<parent link="link3_rot2"/>
		<child link="link3_frame1"/>
		<origin rpy="0 0 0" xyz="0.52 0 -0.03"/>
	</joint>
	
	<link name="link3_frame2">
		<visual>
			<geometry>
				<box size="0.02 0.25 0.56"/>
			</geometry>
			<material name="black"/>
			<origin rpy="0 0 0" xyz="0 0 -0.28"/>
		</visual>
	</link>

	<joint name="link3_frame1_frame2" type="fixed">
		<parent link="link3_frame1"/>
		<child link="link3_frame2"/>
		<origin rpy="0 0 0" xyz="0 0 0.56"/>
	</joint>

	<link name="link3_frame3">
		<visual>
			<geometry>
				<box size="0.65 0.25 0.02"/>
			</geometry>
			<material name="black"/>
			<origin rpy="0 0 0" xyz="-0.325 0 0"/>
		</visual>
	</link>

	<joint name="link3_frame2_frame3" type="fixed">
		<parent link="link3_frame2"/>
		<child link="link3_frame3"/>
		<origin rpy="0 0 0" xyz="0 0 0"/>
	</joint>

	<link name="link4">
		<visual>
			<geometry>
				<box size="0.42 0.20 0.40"/>
			</geometry>	
			<material name="red"/>
			<origin rpy="0 0 0" xyz="0 0 0"/>
		</visual>
	</link>

	<joint name="link3_frame1_link4" type="fixed">
		<parent link="link3_frame1"/>
		<child link="link4"/>
		<origin rpy="0 0 0" xyz="-0.06 0 0.28"/>
	</joint>

	<link name="link4_rot1">
		<visual>
			<geometry>
				<cylinder radius="0.045" length="0.05"/>
			</geometry>	
			<material name="white"/>
			<origin rpy="0 0 0" xyz="0 0 0.025"/>
		</visual>
	</link>

	<joint name="joint4" type="revolute">
		<parent link="link4"/>
		<child link="link4_rot1"/>
		<limit effort="1000.0" lower="-1.5707" upper="1.5707" velocity="0.5"/>
		<origin rpy="0 1.5707 0" xyz="0.21 0 -0.13"/>
		<axis xyz="0 0 1"/>
	</joint>
	
	<link name="link4_rot2">
		<visual>
			<geometry>
				<cylinder radius="0.1" length="0.02"/>
			</geometry>	
			<material name="white"/>
			<origin rpy="0 0 0" xyz="0 0 -0.01"/>
		</visual>
	</link>

	<joint name="link4_rot2_rot1" type="fixed">
		<parent link="link4_rot1"/>
		<child link="link4_rot2"/>
		<origin rpy="0 0 0" xyz="0 0 0.07"/>
	</joint>

  <!-- adding virtual joints for kdl kinematics solver 
			These links and joints are used because
			the kdl solver works with 6 or more dof
		-->

	<link name="vl0">
		<visual>
			<geometry>
				<cylinder radius="0.1" length="0.02"/>
			</geometry>	
			<material name="white"/>
			<origin rpy="0 0 0" xyz="0 0 0"/>
		</visual>
	</link>

	<joint name="vj0" type="revolute">
		<parent link="link4_rot2"/>
		<child link="vl0"/>
		<limit effort="1000.0" lower="-0.005" upper="0.005" velocity="0.5"/>
		<origin rpy="0 0 0" xyz="0 0 0"/>
		<axis xyz="0 1 0"/>
	</joint>
	
	<link name="vl1">
		<visual>
			<geometry>
				<cylinder radius="0.1" length="0.02"/>
			</geometry>	
			<material name="white"/>
			<origin rpy="0 0 0" xyz="0 0 0"/>
		</visual>
	</link>

	<joint name="vj1" type="revolute">
		<parent link="vl0"/>
		<child link="vl1"/>
		<limit effort="1000.0" lower="-0.005" upper="0.005" velocity="0.5"/>
		<origin rpy="0 0 0" xyz="0 0 0"/>
		<axis xyz="1 0 0"/>
	</joint>

	<!-- END of Virtual joints and links -->

	<!-- Gripper -->
    
	<joint name="arm_hand" type="fixed">
		<parent link="vl1"/>
		<child link="hand_base"/>
		<origin rpy="1.57 -1.57 0" xyz="0 0 0.25"/>
	</joint>


    <link name="hand_base">
    <visual>
      <origin xyz="0 0 0" rpy="0 0 0" />
      <geometry>
				<box size="0.5 0.4 0.03"/>
      </geometry>
      <material name="black"/>
    </visual>
  </link>


  <link name="hand_right_finger">
    <visual>
      <origin xyz="0.11 0 0" rpy="0 0 0" />
      <geometry>
        <mesh
            filename="package://robot_urdf/meshes/hand_right_finger.STL"
		    scale="11 11 11" />
      </geometry>
      <material name="white"/>
    </visual>
  </link>

  <joint name="gripper" type="revolute">
    <origin
      xyz="0 -0.15 0.06"
      rpy="-1.57 0 3.0 " />
    <parent link="hand_base" />
    <child link="hand_right_finger" />
    <axis xyz="0 1 0" />
    <limit
      lower="0"
      upper="0.57"
      effort="1000"
      velocity="0.5" />
  </joint>


  <!-- Right finger servo -->
  <link name="right_finger_servo">
    <visual>
      <origin xyz="0 0 0" rpy="0 0 0" />
      <geometry>
        <box size="0.2 0.4 0.4"/>
      </geometry>
      <material name="red"/>
    </visual>
  </link>

  <joint name="hand_right_servo" type="fixed">
    <parent link="hand_base"/>
    <child link="right_finger_servo"/>
    <origin rpy="0 0 0" xyz="0 -0.25 -0.22"/>
  </joint>


  <link name="hand_left_finger">
    <visual>
      <origin xyz="0.11 0 0" rpy="0 0 0" />
      <geometry>
        <mesh
            filename="package://robot_urdf/meshes/hand_left_finger.STL" 
		    scale="11 11 11" />
      </geometry>
      <material name="white"/>
    </visual>
  </link>

  <joint name="gripper_left" type="revolute">
		<mimic joint="gripper"/>
    <origin
      xyz="0 0.15 0.06"
      rpy="-1.57 0 0.52" />
    <parent link="hand_base" />
    <child link="hand_left_finger" />
    <axis xyz="0 -1 0" />
    <limit
      lower="0"
      upper="0.57"
      effort="1000"
      velocity="1000" />
  </joint>


</robot>			
