<?xml version="1.0"?>
<robot name="robot">

	<material name="red">
		<color rgba="0.8 0 0 1"/>
	</material>

	<material name="blue">
		<color rgba="0 0 0.8 1"/>
	</material>
	
	<material name="white">
		<color rgba="1 1 1 1"/>
	</material>

	<material name="black">
		<color rgba="0 0 0 1"/>
	</material>

	<link name="base_link">
		<visual>
			<geometry>
				<box size="0.58 0.46 0.25"/>
			</geometry>
			<origin rpy="0 0 0" xyz="0 0 0"/>
			<material name="red"/>
		</visual>
	</link>

	<link name="link1">
		<visual>
			<geometry>
				<cylinder radius="0.045" length="0.05"/>
			</geometry>
			<material name="white"/>
			<origin rpy="0 0 0" xyz="0 0 -0.025"/>
		</visual>
	</link>
		
	<joint name="joint1" type="revolute">
		<parent link="base_link"/>
		<child link="link1"/>
		<limit effort="1000.0" lower="0" upper="3.1415" velocity="0.5"/>
		<origin rpy="1.5707 0 0" xyz="-0.1 0.23 0"/>
		<axis xyz="0 0 1"/>
	</joint>

	<link name="link2">
		<visual>
			<geometry>
				<cylinder radius="0.1" length="0.02"/>
			</geometry>
			<material name="white"/>
			<origin rpy="0 0 0" xyz="0 0 -0.01"/>
		</visual>
	</link>
		
	<joint name="joint2" type="fixed">
		<parent link="link1"/>
		<child link="link2"/>
		<origin rpy="0 0 0" xyz="0 0 -0.05"/>
	</joint>

</robot>
